<?xml version="1.0"?>

<robot name="AMR">

  <material name="white">
      <color rgba="1 1 1 1"/>
  </material>

  <material name="grey">
      <color rgba="0.5 0.5 0.5 1"/>
  </material>

  <link name="base_footprint">
  </link>
  
  <link name="base_link">
    <visual>
      <origin xyz="0 0 0" rpy="0 0 1.5708"/>
      <geometry>
        <mesh filename="package://robot_urdf/meshes/body.stl" scale="0.001 0.001 0.001"/>
      </geometry>
      <material name="grey"/>
    </visual>

    <collision>
      <origin xyz="0 0 0" rpy="0 0 1.5708"/>
      <geometry>
        <mesh filename="package://robot_urdf/meshes/body.stl" scale="0.001 0.001 0.001"/>
      </geometry>
    </collision>
  </link>

  <link name="left_wheel">
    <visual>
      <origin xyz="0 0 0" rpy="0 0 1.5708"/>
      <geometry>
        <mesh filename="package://robot_urdf/meshes/wheel.stl" scale="0.001 0.001 0.001"/>
      </geometry>
      <material name="grey"/>
    </visual>

    <collision>
      <origin xyz="0 0 0" rpy="0 0 1.5708"/>
      <geometry>
        <mesh filename="package://robot_urdf/meshes/wheel.stl" scale="0.001 0.001 0.001"/>
      </geometry>
    </collision>

  </link>

  <link name="right_wheel">
    <visual>
      <origin xyz="0 0 0" rpy="0 0 1.5708"/>
      <geometry>
        <mesh filename="package://robot_urdf/meshes/wheel.stl" scale="0.001 0.001 0.001"/>
      </geometry>
      <material name="grey"/>
    </visual>

    <collision>
      <origin xyz="0 0 0" rpy="0 0 1.5708"/>
      <geometry>
        <mesh filename="package://robot_urdf/meshes/wheel.stl" scale="0.001 0.001 0.001"/>
      </geometry>
    </collision>
  </link>

  <link name="laser_link">
    <visual>
      <origin xyz="0 0 0" rpy="0 0 0"/>
      <geometry>
        <mesh filename="package://robot_urdf/meshes/rplidar-a2.stl" scale="1 1 1"/>
      </geometry>
    </visual>

    <collision>
      <origin xyz="0 0 0" rpy="0 0 0"/>
      <geometry>
        <mesh filename="package://robot_urdf/meshes/rplidar-a2.stl" scale="1 1 1"/>
      </geometry>
    </collision>
  </link>

  <link name="imu_link">
  </link>

  <link name="camera_link">
    <visual>
      <origin xyz="0 0 0" rpy="0 0 1.5708"/>
      <geometry>
        <mesh filename="package://robot_urdf/meshes/depth_camera.stl" scale="0.001 0.001 0.001"/>
      </geometry>
      <material name="white"/>
    </visual>

    <collision>
      <origin xyz="0 0 0" rpy="0 0 1.5708"/>
      <geometry>
        <mesh filename="package://robot_urdf/meshes/depth_camera.stl" scale="0.001 0.001 0.001"/>
      </geometry>
    </collision>
  </link>

  <link name="arm_link">
  </link>

  <link name="link1">
    <visual>
      <geometry>
        <mesh filename="package://robot_urdf/meshes/base.stl" scale="1 1 1"/>
      </geometry>
      <material name="orange">
        <color rgba="1 0.647 0 1"/>
      </material>
      <origin rpy="0 0 0" xyz="0 0 0"/>
    </visual>
    <collision>
      <geometry>
        <mesh filename="package://robot_urdf/meshes/base.stl" scale="1 1 1"/>
      </geometry>
      <origin rpy="0 0 0" xyz="0 0 0"/>
    </collision>
  </link>

  <link name="link2">
    <visual>
      <geometry>
        <mesh filename="package://robot_urdf/meshes/shoulder.stl" scale="1 1 1"/>
      </geometry>
      <material name="orange">
        <color rgba="1 0.647 0 1"/>
      </material>
      <origin rpy="0 0 0" xyz="0 0 -0.0505"/>
    </visual>
    <collision>
      <geometry>
        <mesh filename="package://robot_urdf/meshes/shoulder.stl" scale="1 1 1"/>
      </geometry>
      <origin rpy="0 0 0" xyz="0 0 -0.0505"/>
    </collision>
  </link>
  
  <link name="link3">
    <visual>
      <geometry>
        <mesh filename="package://robot_urdf/meshes/elbow.stl" scale="1 1 1"/>
      </geometry>
      <material name="orange">
        <color rgba="1 0.647 0 1"/>
      </material>
      <origin rpy="0 0 0" xyz="0 0 -0.1705"/>
    </visual>
    <collision>
      <geometry>
        <mesh filename="package://robot_urdf/meshes/elbow.stl" scale="1 1 1"/>
      </geometry>
      <origin rpy="0 0 0" xyz="0 0 -0.1705"/>
    </collision>
  </link>
  
  <link name="link4">
    <visual>
      <geometry>
        <mesh filename="package://robot_urdf/meshes/wrist_pitch.stl" scale="1 1 1"/>
      </geometry>
      <material name="orange">
        <color rgba="1 0.647 0 1"/>
      </material>
      <origin rpy="0 0 0" xyz="0 0 -0.2905"/>
    </visual>
    <collision>
      <geometry>
        <mesh filename="package://robot_urdf/meshes/wrist_pitch.stl" scale="1 1 1"/>
      </geometry>
      <origin rpy="0 0 0" xyz="0 0 -0.2905"/>
    </collision>
  </link>
  
  <link name="link5">
    <visual>
      <geometry>
        <mesh filename="package://robot_urdf/meshes/wrist_roll.stl" scale="1 1 1"/>
      </geometry>
      <material name="orange">
        <color rgba="1 0.647 0 1"/>
      </material>
      <origin rpy="0 0 0" xyz="0 0 -0.3505"/>
    </visual>
    <collision>
      <geometry>
        <mesh filename="package://robot_urdf/meshes/wrist_roll.stl" scale="1 1 1"/>
      </geometry>
      <origin rpy="0 0 0" xyz="0 0 -0.3505"/>
    </collision>
  </link>
  
  <link name="gripper_base">
    <visual>
      <geometry>
        <mesh filename="package://robot_urdf/meshes/gripper_base.stl" scale="1 1 1"/>
      </geometry>
      <material name="white"/>
      <origin rpy="0 0 0" xyz="0 0 -0.357"/>
    </visual>
    <collision>
      <geometry>
        <mesh filename="package://robot_urdf/meshes/gripper_base.stl" scale="1 1 1"/>
      </geometry>
      <origin rpy="0 0 0" xyz="0 0 -0.357"/>
    </collision>
  </link>
  
  <link name="gripper_fix">
    <visual>
      <geometry>
        <mesh filename="package://robot_urdf/meshes/gripper_fix.stl" scale="1 1 1"/>
      </geometry>
      <material name="white"/>
      <origin rpy="0 0 0" xyz="0 0 -0.36399"/>
    </visual>
    <collision>
      <geometry>
        <mesh filename="package://robot_urdf/meshes/gripper_fix.stl" scale="1 1 1"/>
      </geometry>
      <origin rpy="0 0 0" xyz="0 0 -0.36399"/>
    </collision>
  </link>
  
  <link name="gripper_movable">
    <visual>
      <geometry>
        <mesh filename="package://robot_urdf/meshes/gripper_movable.stl" scale="1 1 1"/>
      </geometry>
      <material name="white"/>
      <origin rpy="0 0 0" xyz="-0.01559 0 -0.36399"/>
    </visual>
    <collision>
      <geometry>
        <mesh filename="package://robot_urdf/meshes/gripper_movable.stl" scale="1 1 1"/>
      </geometry>
      <origin rpy="0 0 0" xyz="-0.01559 0 -0.36399"/>
    </collision>
  </link>

  <joint name="base_joint" type="fixed">
    <parent link="base_footprint"/>
    <child link="base_link"/>
    <origin rpy="0 0 0" xyz="0 0 0.0856"/>
    <axis xyz="0 0 0"/>
  </joint>

  <joint name="L_wheel_joint" type="fixed">
    <parent link="base_link"/>
    <child link="left_wheel"/>
    <origin rpy="0 0 0" xyz="-0.0225 0.1475 -0.0242"/>
    <axis xyz="0 0 0"/>
  </joint>

  <joint name="R_wheel_joint" type="fixed">
    <parent link="base_link"/>
    <child link="right_wheel"/>
    <origin rpy="-3.14159 0 0" xyz="-0.0225 -0.1475 -0.0242"/>
    <axis xyz="0 0 0"/>
  </joint>

  <joint name="laser_joint" type="fixed">
    <parent link="base_link"/>
    <child link="laser_link"/>
    <origin rpy="0 0 0" xyz="0.2305 0 0.08"/>
    <axis xyz="0 0 0"/>
  </joint>

  <joint name="imu_joint" type="fixed">
    <parent link="base_footprint"/>
    <child link="imu_link"/>
    <origin rpy="0 0 0" xyz="0 0 0"/>
    <axis xyz="0 0 0"/>
  </joint>

  <joint name="camera_joint" type="fixed">
    <parent link="base_link"/>
    <child link="camera_link"/>
    <origin rpy="0 0 0" xyz="0.245 0 -0.027"/>
    <axis xyz="0 0 0"/>
  </joint>

  <joint name="arm_joint" type="fixed">
    <parent link="base_link"/>
    <child link="arm_link"/>
    <origin rpy="0 0 0" xyz="0.12375 0 0.045"/>
    <axis xyz="0 0 0"/>
  </joint>

  <joint name="base" type="revolute">
    <axis xyz="0 0 -1"/>
    <limit effort="1000.0" lower="0.0" upper="3.141592653589793" velocity="4.0"/>
    <origin rpy="0 0 0" xyz="0 0 0"/>
    <parent link="arm_link"/>
    <child link="link1"/>
  </joint>

  <joint name="shoulder" type="revolute">
    <axis xyz="1 0 0"/>
    <limit effort="1000.0" lower="0.2617993877991494" upper="2.8797932657906435" velocity="4.0"/>
    <origin rpy="-1.5707963267948966 0 0" xyz="0 0 0.0505"/>
    <parent link="link1"/>
    <child link="link2"/>
  </joint>
  
  <joint name="elbow" type="revolute">
    <axis xyz="1 0 0"/>
    <limit effort="1000.0" lower="0" upper="3.141592653589793" velocity="4.0"/>
    <origin rpy="-1.5707963267948966 0 0" xyz="0 0 0.1205"/>
    <parent link="link2"/>
    <child link="link3"/>
  </joint>
  
  <joint name="wrist_pitch" type="revolute">
    <axis xyz="1 0 0"/>
    <limit effort="1000.0" lower="0" upper="3.141592653589793" velocity="4.0"/>
    <origin rpy="-1.5707963267948966 0 0" xyz="0 0 0.1205"/>
    <parent link="link3"/>
    <child link="link4"/>
  </joint>
  
  <joint name="wrist_roll" type="revolute">
    <axis xyz="0 0 -1"/>
    <limit effort="1000.0" lower="0.0" upper="3.141592653589793" velocity="4.0"/>
    <origin rpy="0 0 0" xyz="0 0.0 0.06"/>
    <parent link="link4"/>
    <child link="link5"/>
  </joint>
  
  <joint name="gripper_base" type="fixed">
    <origin rpy="0 0 0" xyz="0 0.0 0.0065"/>
    <parent link="link5"/>
    <child link="gripper_base"/>
  </joint>
  
  <joint name="gripper_fix" type="fixed">
    <origin rpy="0 0 0" xyz="0 0.0 0.007"/>
    <parent link="gripper_base"/>
    <child link="gripper_fix"/>
  </joint>
  
  <joint name="gripper_movable" type="revolute">
    <axis xyz="0 -1 0"/>
    <limit effort="1000.0" lower="0.17453292519943295" upper="1.2740903539558606" velocity="4.0"/>
    <origin rpy="0 0 0" xyz="0.01559 0 0.007"/>
    <parent link="gripper_base"/>
    <child link="gripper_movable"/>
  </joint>
  
</robot>
